<html xmlns:string="xalan://java.lang.String" xmlns:lxslt="http://xml.apache.org/xslt">
<head>
<META http-equiv="Content-Type" content="text/html; charset=UTF-8">
<title>Unit Test Results: All Errors</title>
<link rel="stylesheet" type="text/css" title="Style" href="stylesheet.css">
</head>
<body onload="open('allclasses-frame.html','classListFrame')">
<h1>Unit Test Results.</h1>
<table width="100%">
<tr>
<td align="left"></td><td align="right">Designed for use with <a href="http://www.junit.org/">JUnit</a> and <a href="http://ant.apache.org/">Ant</a>.</td>
</tr>
</table>
<hr size="1">
<h2>All Errors</h2>
<table class="details" border="0" cellpadding="5" cellspacing="2" width="95%">
<tr valign="top">
<th>Class</th><th>Name</th><th>Status</th><th width="80%">Type</th><th nowrap>Time(s)</th>
</tr>
<tr valign="top" class="Error">
<td><a href="org/ptolemy/ptango/lib/webSocket/test/junit/31_JUnitTclTest.html">JUnitTclTest</a></td><td><a name="[2] /home/travis/build/icyphy/ptII/org/ptolemy/ptango/lib/webSocket/test/auto/RemoteSocketSingleReaderWriter.xml (RunModel)"></a><a href="org/ptolemy/ptango/lib/webSocket/test/junit/31_JUnitTclTest.html#[2] /home/travis/build/icyphy/ptII/org/ptolemy/ptango/lib/webSocket/test/auto/RemoteSocketSingleReaderWriter.xml (RunModel)">[2] /home/travis/build/icyphy/ptII/org/ptolemy/ptango/lib/webSocket/test/auto/RemoteSocketSingleReaderWriter.xml (RunModel)</a></td><td>Error</td><td>N/A<br>
<br>
<code>java.lang.reflect.InvocationTargetException<br>	at java.lang.reflect.Constructor.newInstance(Constructor.java:423)<br>	at ptolemy.util.test.junit.AutoTests.RunModel(AutoTests.java:193)<br>	at junitparams.internal.InvokeParameterisedMethod.evaluate(InvokeParameterisedMethod.java:102)<br>Caused by: java.nio.channels.UnresolvedAddressException<br>	at sun.nio.ch.Net.checkAddress(Net.java:101)<br>	at sun.nio.ch.SocketChannelImpl.connect(SocketChannelImpl.java:622)<br>	at org.eclipse.jetty.websocket.WebSocketClient.open(WebSocketClient.java:346)<br>	at org.ptolemy.ptango.lib.webSocket.WebSocketEndpointManager._open(WebSocketEndpointManager.java:366)<br>	at org.ptolemy.ptango.lib.webSocket.WebSocketEndpointManager.subscribe(WebSocketEndpointManager.java:285)<br>	at org.ptolemy.ptango.lib.webSocket.WebSocketWriter.initialize(WebSocketWriter.java:170)<br>	at ptolemy.actor.Director.initialize(Director.java:938)<br>	at ptolemy.actor.Director.initialize(Director.java:907)<br>	at ptolemy.domains.de.kernel.DEDirector.initialize(DEDirector.java:944)<br>	at ptolemy.actor.CompositeActor.initialize(CompositeActor.java:935)<br>	at ptolemy.actor.Manager.initialize(Manager.java:724)<br>	at ptolemy.actor.Manager.execute(Manager.java:356)<br>	at ptolemy.actor.Manager.run(Manager.java:1263)<br>	at ptolemy.actor.Manager$PtolemyRunThread.run(Manager.java:1915)<br>
</code></td><td>0.114</td>
</tr>
<tr valign="top" class="Error">
<td><a href="ptolemy/actor/lib/jjs/test/junit/74_JUnitTclTest.html">JUnitTclTest</a></td><td><a name="[32] /home/travis/build/icyphy/ptII/ptolemy/actor/lib/jjs/test/auto/JavaScript8.xml (RunModel)"></a><a href="ptolemy/actor/lib/jjs/test/junit/74_JUnitTclTest.html#[32] /home/travis/build/icyphy/ptII/ptolemy/actor/lib/jjs/test/auto/JavaScript8.xml (RunModel)">[32] /home/travis/build/icyphy/ptII/ptolemy/actor/lib/jjs/test/auto/JavaScript8.xml (RunModel)</a></td><td>Error</td><td>N/A<br>
<br>
<code>java.lang.reflect.InvocationTargetException<br>	at java.lang.reflect.Constructor.newInstance(Constructor.java:423)<br>	at ptolemy.util.test.junit.AutoTests.RunModel(AutoTests.java:193)<br>	at junitparams.internal.InvokeParameterisedMethod.evaluate(InvokeParameterisedMethod.java:102)<br>Caused by: ptolemy.kernel.util.IllegalActionException: Expected a message starting with:<br> was initialized and<br>But got:<br>Exception(s) thrown during wrapup:<br>ptolemy.kernel.util.IllegalActionException:  was initialized and should have handled an exception but did not see any.<br>  in .JavaScript8.TestExceptionAttribute========<br>ptolemy.kernel.util.IllegalActionException: Exceptions occurred during wrapup:<br>ptolemy.kernel.util.IllegalActionException: The test produced only 0 tokens, yet the correctValues parameter was expecting 3 tokens.<br>  in .JavaScript8.NonStrictTest<br>
<br>  in .JavaScript8.SDF Director<br>Because:<br>The test produced only 0 tokens, yet the correctValues parameter was expecting 3 tokens.<br>  in .JavaScript8.NonStrictTest========<br>
<br>  in .JavaScript8<br>Because:<br> was initialized and should have handled an exception but did not see any.<br>  in .JavaScript8.TestExceptionAttribute<br>  in .JavaScript8.TestExceptionAttribute<br>Because:<br>Exception(s) thrown during wrapup:<br>ptolemy.kernel.util.IllegalActionException:  was initialized and should have handled an exception but did not see any.<br>  in .JavaScript8.TestExceptionAttribute========<br>ptolemy.kernel.util.IllegalActionException: Exceptions occurred during wrapup:<br>ptolemy.kernel.util.IllegalActionException: The test produced only 0 tokens, yet the correctValues parameter was expecting 3 tokens.<br>  in .JavaScript8.NonStrictTest<br>
<br>  in .JavaScript8.SDF Director<br>Because:<br>The test produced only 0 tokens, yet the correctValues parameter was expecting 3 tokens.<br>  in .JavaScript8.NonStrictTest========<br>
<br>  in .JavaScript8<br>Because:<br> was initialized and should have handled an exception but did not see any.<br>  in .JavaScript8.TestExceptionAttribute<br>	at ptolemy.actor.lib.TestExceptionAttribute.handleException(TestExceptionAttribute.java:185)<br>	at ptolemy.actor.Manager.execute(Manager.java:476)<br>	at ptolemy.actor.Manager.run(Manager.java:1263)<br>	at ptolemy.actor.Manager$PtolemyRunThread.run(Manager.java:1915)<br>Caused by: ptolemy.kernel.util.IllegalActionException: Exception(s) thrown during wrapup:<br>ptolemy.kernel.util.IllegalActionException:  was initialized and should have handled an exception but did not see any.<br>  in .JavaScript8.TestExceptionAttribute========<br>ptolemy.kernel.util.IllegalActionException: Exceptions occurred during wrapup:<br>ptolemy.kernel.util.IllegalActionException: The test produced only 0 tokens, yet the correctValues parameter was expecting 3 tokens.<br>  in .JavaScript8.NonStrictTest<br>
<br>  in .JavaScript8.SDF Director<br>Because:<br>The test produced only 0 tokens, yet the correctValues parameter was expecting 3 tokens.<br>  in .JavaScript8.NonStrictTest========<br>
<br>  in .JavaScript8<br>Because:<br> was initialized and should have handled an exception but did not see any.<br>  in .JavaScript8.TestExceptionAttribute<br>	at ptolemy.actor.CompositeActor.wrapup(CompositeActor.java:2780)<br>	at ptolemy.actor.Manager.wrapup(Manager.java:1512)<br>	at ptolemy.actor.Manager.execute(Manager.java:407)<br>Caused by: ptolemy.kernel.util.IllegalActionException:  was initialized and should have handled an exception but did not see any.<br>  in .JavaScript8.TestExceptionAttribute<br>	at ptolemy.actor.lib.TestExceptionAttribute.wrapup(TestExceptionAttribute.java:213)<br>	at ptolemy.actor.CompositeActor.wrapup(CompositeActor.java:2705)<br>
</code></td><td>5.991</td>
</tr>
<tr valign="top" class="Error">
<td><a href="ptolemy/actor/lib/test/junit/83_JUnitTclTest.html">JUnitTclTest</a></td><td><a name="[362] /home/travis/build/icyphy/ptII/ptolemy/actor/lib/test/auto/TestExceptionAttribute1.xml (RunModel)"></a><a href="ptolemy/actor/lib/test/junit/83_JUnitTclTest.html#[362] /home/travis/build/icyphy/ptII/ptolemy/actor/lib/test/auto/TestExceptionAttribute1.xml (RunModel)">[362] /home/travis/build/icyphy/ptII/ptolemy/actor/lib/test/auto/TestExceptionAttribute1.xml (RunModel)</a></td><td>Error</td><td>N/A<br>
<br>
<code>java.lang.reflect.InvocationTargetException<br>	at java.lang.reflect.Constructor.newInstance(Constructor.java:423)<br>	at ptolemy.util.test.junit.AutoTests.RunModel(AutoTests.java:193)<br>	at junitparams.internal.InvokeParameterisedMethod.evaluate(InvokeParameterisedMethod.java:102)<br>Caused by: ptolemy.kernel.util.IllegalActionException: Expected:<br> was initialized and should have handled an exception but did not see any.<br>  in .TestExceptionAttribute1.TestExceptionAttribute<br>But got:<br>Exception(s) thrown during wrapup:<br>ptolemy.kernel.util.IllegalActionException:  was initialized and should have handled an exception but did not see any.<br>  in .TestExceptionAttribute1.TestExceptionAttribute========<br>
<br>  in .TestExceptionAttribute1<br>Because:<br> was initialized and should have handled an exception but did not see any.<br>  in .TestExceptionAttribute1.TestExceptionAttribute<br>  in .TestExceptionAttribute1.TestExceptionAttribute<br>Because:<br>Exception(s) thrown during wrapup:<br>ptolemy.kernel.util.IllegalActionException:  was initialized and should have handled an exception but did not see any.<br>  in .TestExceptionAttribute1.TestExceptionAttribute========<br>
<br>  in .TestExceptionAttribute1<br>Because:<br> was initialized and should have handled an exception but did not see any.<br>  in .TestExceptionAttribute1.TestExceptionAttribute<br>	at ptolemy.actor.lib.TestExceptionAttribute.handleException(TestExceptionAttribute.java:174)<br>	at ptolemy.actor.Manager.execute(Manager.java:476)<br>	at ptolemy.actor.Manager.run(Manager.java:1263)<br>	at ptolemy.actor.Manager$PtolemyRunThread.run(Manager.java:1915)<br>Caused by: ptolemy.kernel.util.IllegalActionException: Exception(s) thrown during wrapup:<br>ptolemy.kernel.util.IllegalActionException:  was initialized and should have handled an exception but did not see any.<br>  in .TestExceptionAttribute1.TestExceptionAttribute========<br>
<br>  in .TestExceptionAttribute1<br>Because:<br> was initialized and should have handled an exception but did not see any.<br>  in .TestExceptionAttribute1.TestExceptionAttribute<br>	at ptolemy.actor.CompositeActor.wrapup(CompositeActor.java:2780)<br>	at ptolemy.actor.Manager.wrapup(Manager.java:1512)<br>	at ptolemy.actor.Manager.execute(Manager.java:407)<br>Caused by: ptolemy.kernel.util.IllegalActionException:  was initialized and should have handled an exception but did not see any.<br>  in .TestExceptionAttribute1.TestExceptionAttribute<br>	at ptolemy.actor.lib.TestExceptionAttribute.wrapup(TestExceptionAttribute.java:213)<br>	at ptolemy.actor.CompositeActor.wrapup(CompositeActor.java:2705)<br>
</code></td><td>0.007</td>
</tr>
<tr valign="top" class="Error">
<td><a href="ptolemy/actor/lib/test/junit/83_JUnitTclTest.html">JUnitTclTest</a></td><td><a name="[363] /home/travis/build/icyphy/ptII/ptolemy/actor/lib/test/auto/TestExceptionAttribute2.xml (RunModel)"></a><a href="ptolemy/actor/lib/test/junit/83_JUnitTclTest.html#[363] /home/travis/build/icyphy/ptII/ptolemy/actor/lib/test/auto/TestExceptionAttribute2.xml (RunModel)">[363] /home/travis/build/icyphy/ptII/ptolemy/actor/lib/test/auto/TestExceptionAttribute2.xml (RunModel)</a></td><td>Error</td><td>N/A<br>
<br>
<code>java.lang.reflect.InvocationTargetException<br>	at java.lang.reflect.Constructor.newInstance(Constructor.java:423)<br>	at ptolemy.util.test.junit.AutoTests.RunModel(AutoTests.java:193)<br>	at junitparams.internal.InvokeParameterisedMethod.evaluate(InvokeParameterisedMethod.java:102)<br>Caused by: ptolemy.kernel.util.IllegalActionException: Expected:<br> was initialized and should have handled an exception but did not see any.<br>  in .TestExceptionAttribute2.TestExceptionAttribute<br>But got:<br>Exception(s) thrown during wrapup:<br>ptolemy.kernel.util.IllegalActionException:  was initialized and should have handled an exception but did not see any.<br>  in .TestExceptionAttribute2.TestExceptionAttribute========<br>ptolemy.kernel.util.IllegalActionException:  was initialized and should have handled an exception but did not see any.<br>  in .TestExceptionAttribute2.TestExceptionAttribute2========<br>
<br>  in .TestExceptionAttribute2<br>Because:<br> was initialized and should have handled an exception but did not see any.<br>  in .TestExceptionAttribute2.TestExceptionAttribute<br>  in .TestExceptionAttribute2.TestExceptionAttribute<br>Because:<br>Exception(s) thrown during wrapup:<br>ptolemy.kernel.util.IllegalActionException:  was initialized and should have handled an exception but did not see any.<br>  in .TestExceptionAttribute2.TestExceptionAttribute========<br>ptolemy.kernel.util.IllegalActionException:  was initialized and should have handled an exception but did not see any.<br>  in .TestExceptionAttribute2.TestExceptionAttribute2========<br>
<br>  in .TestExceptionAttribute2<br>Because:<br> was initialized and should have handled an exception but did not see any.<br>  in .TestExceptionAttribute2.TestExceptionAttribute<br>	at ptolemy.actor.lib.TestExceptionAttribute.handleException(TestExceptionAttribute.java:174)<br>	at ptolemy.actor.Manager.execute(Manager.java:476)<br>	at ptolemy.actor.Manager.run(Manager.java:1263)<br>	at ptolemy.actor.Manager$PtolemyRunThread.run(Manager.java:1915)<br>Caused by: ptolemy.kernel.util.IllegalActionException: Exception(s) thrown during wrapup:<br>ptolemy.kernel.util.IllegalActionException:  was initialized and should have handled an exception but did not see any.<br>  in .TestExceptionAttribute2.TestExceptionAttribute========<br>ptolemy.kernel.util.IllegalActionException:  was initialized and should have handled an exception but did not see any.<br>  in .TestExceptionAttribute2.TestExceptionAttribute2========<br>
<br>  in .TestExceptionAttribute2<br>Because:<br> was initialized and should have handled an exception but did not see any.<br>  in .TestExceptionAttribute2.TestExceptionAttribute<br>	at ptolemy.actor.CompositeActor.wrapup(CompositeActor.java:2780)<br>	at ptolemy.actor.Manager.wrapup(Manager.java:1512)<br>	at ptolemy.actor.Manager.execute(Manager.java:407)<br>Caused by: ptolemy.kernel.util.IllegalActionException:  was initialized and should have handled an exception but did not see any.<br>  in .TestExceptionAttribute2.TestExceptionAttribute<br>	at ptolemy.actor.lib.TestExceptionAttribute.wrapup(TestExceptionAttribute.java:213)<br>	at ptolemy.actor.CompositeActor.wrapup(CompositeActor.java:2705)<br>
</code></td><td>0.012</td>
</tr>
<tr valign="top" class="Error">
<td><a href="ptolemy/actor/lib/test/junit/83_JUnitTclTest.html">JUnitTclTest</a></td><td><a name="[366] /home/travis/build/icyphy/ptII/ptolemy/actor/lib/test/auto/TestExceptionHandler1.xml (RunModel)"></a><a href="ptolemy/actor/lib/test/junit/83_JUnitTclTest.html#[366] /home/travis/build/icyphy/ptII/ptolemy/actor/lib/test/auto/TestExceptionHandler1.xml (RunModel)">[366] /home/travis/build/icyphy/ptII/ptolemy/actor/lib/test/auto/TestExceptionHandler1.xml (RunModel)</a></td><td>Error</td><td>N/A<br>
<br>
<code>java.lang.reflect.InvocationTargetException<br>	at java.lang.reflect.Constructor.newInstance(Constructor.java:423)<br>	at ptolemy.util.test.junit.AutoTests.RunModel(AutoTests.java:193)<br>	at junitparams.internal.InvokeParameterisedMethod.evaluate(InvokeParameterisedMethod.java:102)<br>Caused by: ptolemy.kernel.util.IllegalActionException: Expected:<br>Exceptions occurred during wrapup:<br>ptolemy.kernel.util.IllegalActionException:  should have handled an exception but did not see any.<br>  in .TestExceptionHandler1.TestExceptionHandler<br>
<br>  in .TestExceptionHandler1.DE Director<br>Because:<br> should have handled an exception but did not see any.<br>  in .TestExceptionHandler1.TestExceptionHandler<br>But got:<br>Exception(s) thrown during wrapup:<br>ptolemy.kernel.util.IllegalActionException: Exceptions occurred during wrapup:<br>ptolemy.kernel.util.IllegalActionException:  should have handled an exception but did not see any.<br>  in .TestExceptionHandler1.TestExceptionHandler<br>
<br>  in .TestExceptionHandler1.DE Director<br>Because:<br> should have handled an exception but did not see any.<br>  in .TestExceptionHandler1.TestExceptionHandler========<br>
<br>  in .TestExceptionHandler1<br>Because:<br>Exceptions occurred during wrapup:<br>ptolemy.kernel.util.IllegalActionException:  should have handled an exception but did not see any.<br>  in .TestExceptionHandler1.TestExceptionHandler<br>
<br>  in .TestExceptionHandler1.DE Director<br>Because:<br> should have handled an exception but did not see any.<br>  in .TestExceptionHandler1.TestExceptionHandler<br>  in .TestExceptionHandler1.TestExceptionHandler<br>Because:<br>Exception(s) thrown during wrapup:<br>ptolemy.kernel.util.IllegalActionException: Exceptions occurred during wrapup:<br>ptolemy.kernel.util.IllegalActionException:  should have handled an exception but did not see any.<br>  in .TestExceptionHandler1.TestExceptionHandler<br>
<br>  in .TestExceptionHandler1.DE Director<br>Because:<br> should have handled an exception but did not see any.<br>  in .TestExceptionHandler1.TestExceptionHandler========<br>
<br>  in .TestExceptionHandler1<br>Because:<br>Exceptions occurred during wrapup:<br>ptolemy.kernel.util.IllegalActionException:  should have handled an exception but did not see any.<br>  in .TestExceptionHandler1.TestExceptionHandler<br>
<br>  in .TestExceptionHandler1.DE Director<br>Because:<br> should have handled an exception but did not see any.<br>  in .TestExceptionHandler1.TestExceptionHandler<br>	at ptolemy.actor.lib.TestExceptionHandler.handleException(TestExceptionHandler.java:142)<br>	at ptolemy.actor.Manager.execute(Manager.java:476)<br>	at ptolemy.actor.Manager.run(Manager.java:1263)<br>	at ptolemy.actor.Manager$PtolemyRunThread.run(Manager.java:1915)<br>Caused by: ptolemy.kernel.util.IllegalActionException: Exception(s) thrown during wrapup:<br>ptolemy.kernel.util.IllegalActionException: Exceptions occurred during wrapup:<br>ptolemy.kernel.util.IllegalActionException:  should have handled an exception but did not see any.<br>  in .TestExceptionHandler1.TestExceptionHandler<br>
<br>  in .TestExceptionHandler1.DE Director<br>Because:<br> should have handled an exception but did not see any.<br>  in .TestExceptionHandler1.TestExceptionHandler========<br>
<br>  in .TestExceptionHandler1<br>Because:<br>Exceptions occurred during wrapup:<br>ptolemy.kernel.util.IllegalActionException:  should have handled an exception but did not see any.<br>  in .TestExceptionHandler1.TestExceptionHandler<br>
<br>  in .TestExceptionHandler1.DE Director<br>Because:<br> should have handled an exception but did not see any.<br>  in .TestExceptionHandler1.TestExceptionHandler<br>	at ptolemy.actor.CompositeActor.wrapup(CompositeActor.java:2780)<br>	at ptolemy.actor.Manager.wrapup(Manager.java:1512)<br>	at ptolemy.actor.Manager.execute(Manager.java:407)<br>Caused by: ptolemy.kernel.util.IllegalActionException: Exceptions occurred during wrapup:<br>ptolemy.kernel.util.IllegalActionException:  should have handled an exception but did not see any.<br>  in .TestExceptionHandler1.TestExceptionHandler<br>
<br>  in .TestExceptionHandler1.DE Director<br>Because:<br> should have handled an exception but did not see any.<br>  in .TestExceptionHandler1.TestExceptionHandler<br>	at ptolemy.actor.Director.wrapup(Director.java:1736)<br>	at ptolemy.domains.de.kernel.DEDirector.wrapup(DEDirector.java:1527)<br>	at ptolemy.actor.CompositeActor.wrapup(CompositeActor.java:2768)<br>Caused by: ptolemy.kernel.util.IllegalActionException:  should have handled an exception but did not see any.<br>  in .TestExceptionHandler1.TestExceptionHandler<br>	at ptolemy.actor.lib.TestExceptionHandler.wrapup(TestExceptionHandler.java:168)<br>	at ptolemy.actor.Director.wrapup(Director.java:1722)<br>
</code></td><td>0.013</td>
</tr>
<tr valign="top" class="Error">
<td><a href="ptolemy/actor/lib/test/junit/83_JUnitTclTest.html">JUnitTclTest</a></td><td><a name="[367] /home/travis/build/icyphy/ptII/ptolemy/actor/lib/test/auto/TestExceptionHandler2.xml (RunModel)"></a><a href="ptolemy/actor/lib/test/junit/83_JUnitTclTest.html#[367] /home/travis/build/icyphy/ptII/ptolemy/actor/lib/test/auto/TestExceptionHandler2.xml (RunModel)">[367] /home/travis/build/icyphy/ptII/ptolemy/actor/lib/test/auto/TestExceptionHandler2.xml (RunModel)</a></td><td>Error</td><td>N/A<br>
<br>
<code>java.lang.reflect.InvocationTargetException<br>	at java.lang.reflect.Constructor.newInstance(Constructor.java:423)<br>	at ptolemy.util.test.junit.AutoTests.RunModel(AutoTests.java:193)<br>	at junitparams.internal.InvokeParameterisedMethod.evaluate(InvokeParameterisedMethod.java:102)<br>Caused by: ptolemy.kernel.util.IllegalActionException: Expected:<br>Exceptions occurred during wrapup:<br>ptolemy.kernel.util.IllegalActionException:  should have handled an exception but did not see any.<br>  in .TestExceptionHandler2.TestExceptionHandler<br>ptolemy.kernel.util.IllegalActionException:  should have handled an exception but did not see any.<br>  in .TestExceptionHandler2.TestExceptionHandler2<br>
<br>  in .TestExceptionHandler2.DE Director<br>Because:<br> should have handled an exception but did not see any.<br>  in .TestExceptionHandler2.TestExceptionHandler<br>But got:<br>Exception(s) thrown during wrapup:<br>ptolemy.kernel.util.IllegalActionException: Exceptions occurred during wrapup:<br>ptolemy.kernel.util.IllegalActionException:  should have handled an exception but did not see any.<br>  in .TestExceptionHandler2.TestExceptionHandler<br>ptolemy.kernel.util.IllegalActionException:  should have handled an exception but did not see any.<br>  in .TestExceptionHandler2.TestExceptionHandler2<br>
<br>  in .TestExceptionHandler2.DE Director<br>Because:<br> should have handled an exception but did not see any.<br>  in .TestExceptionHandler2.TestExceptionHandler========<br>
<br>  in .TestExceptionHandler2<br>Because:<br>Exceptions occurred during wrapup:<br>ptolemy.kernel.util.IllegalActionException:  should have handled an exception but did not see any.<br>  in .TestExceptionHandler2.TestExceptionHandler<br>ptolemy.kernel.util.IllegalActionException:  should have handled an exception but did not see any.<br>  in .TestExceptionHandler2.TestExceptionHandler2<br>
<br>  in .TestExceptionHandler2.DE Director<br>Because:<br> should have handled an exception but did not see any.<br>  in .TestExceptionHandler2.TestExceptionHandler<br>  in .TestExceptionHandler2.TestExceptionHandler<br>Because:<br>Exception(s) thrown during wrapup:<br>ptolemy.kernel.util.IllegalActionException: Exceptions occurred during wrapup:<br>ptolemy.kernel.util.IllegalActionException:  should have handled an exception but did not see any.<br>  in .TestExceptionHandler2.TestExceptionHandler<br>ptolemy.kernel.util.IllegalActionException:  should have handled an exception but did not see any.<br>  in .TestExceptionHandler2.TestExceptionHandler2<br>
<br>  in .TestExceptionHandler2.DE Director<br>Because:<br> should have handled an exception but did not see any.<br>  in .TestExceptionHandler2.TestExceptionHandler========<br>
<br>  in .TestExceptionHandler2<br>Because:<br>Exceptions occurred during wrapup:<br>ptolemy.kernel.util.IllegalActionException:  should have handled an exception but did not see any.<br>  in .TestExceptionHandler2.TestExceptionHandler<br>ptolemy.kernel.util.IllegalActionException:  should have handled an exception but did not see any.<br>  in .TestExceptionHandler2.TestExceptionHandler2<br>
<br>  in .TestExceptionHandler2.DE Director<br>Because:<br> should have handled an exception but did not see any.<br>  in .TestExceptionHandler2.TestExceptionHandler<br>	at ptolemy.actor.lib.TestExceptionHandler.handleException(TestExceptionHandler.java:142)<br>	at ptolemy.actor.Manager.execute(Manager.java:476)<br>	at ptolemy.actor.Manager.run(Manager.java:1263)<br>	at ptolemy.actor.Manager$PtolemyRunThread.run(Manager.java:1915)<br>Caused by: ptolemy.kernel.util.IllegalActionException: Exception(s) thrown during wrapup:<br>ptolemy.kernel.util.IllegalActionException: Exceptions occurred during wrapup:<br>ptolemy.kernel.util.IllegalActionException:  should have handled an exception but did not see any.<br>  in .TestExceptionHandler2.TestExceptionHandler<br>ptolemy.kernel.util.IllegalActionException:  should have handled an exception but did not see any.<br>  in .TestExceptionHandler2.TestExceptionHandler2<br>
<br>  in .TestExceptionHandler2.DE Director<br>Because:<br> should have handled an exception but did not see any.<br>  in .TestExceptionHandler2.TestExceptionHandler========<br>
<br>  in .TestExceptionHandler2<br>Because:<br>Exceptions occurred during wrapup:<br>ptolemy.kernel.util.IllegalActionException:  should have handled an exception but did not see any.<br>  in .TestExceptionHandler2.TestExceptionHandler<br>ptolemy.kernel.util.IllegalActionException:  should have handled an exception but did not see any.<br>  in .TestExceptionHandler2.TestExceptionHandler2<br>
<br>  in .TestExceptionHandler2.DE Director<br>Because:<br> should have handled an exception but did not see any.<br>  in .TestExceptionHandler2.TestExceptionHandler<br>	at ptolemy.actor.CompositeActor.wrapup(CompositeActor.java:2780)<br>	at ptolemy.actor.Manager.wrapup(Manager.java:1512)<br>	at ptolemy.actor.Manager.execute(Manager.java:407)<br>Caused by: ptolemy.kernel.util.IllegalActionException: Exceptions occurred during wrapup:<br>ptolemy.kernel.util.IllegalActionException:  should have handled an exception but did not see any.<br>  in .TestExceptionHandler2.TestExceptionHandler<br>ptolemy.kernel.util.IllegalActionException:  should have handled an exception but did not see any.<br>  in .TestExceptionHandler2.TestExceptionHandler2<br>
<br>  in .TestExceptionHandler2.DE Director<br>Because:<br> should have handled an exception but did not see any.<br>  in .TestExceptionHandler2.TestExceptionHandler<br>	at ptolemy.actor.Director.wrapup(Director.java:1736)<br>	at ptolemy.domains.de.kernel.DEDirector.wrapup(DEDirector.java:1527)<br>	at ptolemy.actor.CompositeActor.wrapup(CompositeActor.java:2768)<br>Caused by: ptolemy.kernel.util.IllegalActionException:  should have handled an exception but did not see any.<br>  in .TestExceptionHandler2.TestExceptionHandler<br>	at ptolemy.actor.lib.TestExceptionHandler.wrapup(TestExceptionHandler.java:168)<br>	at ptolemy.actor.Director.wrapup(Director.java:1722)<br>
</code></td><td>0.023</td>
</tr>
<tr valign="top" class="Error">
<td><a href="ptolemy/configs/test/junit/108_JUnitTclTest.html">JUnitTclTest</a></td><td><a name="[2] /home/travis/build/icyphy/ptII/ptolemy/configs/test/checkFullConstraints.tcl (RunTclFile)"></a><a href="ptolemy/configs/test/junit/108_JUnitTclTest.html#[2] /home/travis/build/icyphy/ptII/ptolemy/configs/test/checkFullConstraints.tcl (RunTclFile)">[2] /home/travis/build/icyphy/ptII/ptolemy/configs/test/checkFullConstraints.tcl (RunTclFile)</a></td><td>Error</td><td>Evaluating the Tcl file "/home/travis/build/icyphy/ptII/ptolemy/configs/test/checkFullConstraints.tcl"resulted in a TclException being thrown.
The Tcl errorInfo variable could not be obtained.
java.lang.Exception: Evaluating the Tcl file "/home/travis/build/icyphy/ptII/ptolemy/configs/test/checkFullConstraints.tcl"resulted in a TclException being thrown.
The Tcl errorInfo global variable has the value:
ptolemy.kernel.util.InvalidStateException: Failed to populate Library
  in .configuration.actor library.MoreLibraries.Accessors.dashboard
Because:
Loading accessor failed: GraphComponent.js
  in .configuration.actor library.MoreLibraries.Accessors.dashboard
Because:
https://ptolemy.berkeley.edu/accessors/dashboard/GraphComponent.js
    while executing
"$configuration allAtomicEntityList"
    invoked from within
"set entityList [$configuration allAtomicEntityList]"
    (procedure "checkConstraints" line 33)
    invoked from within
"checkConstraints full/configuration.xml"
    (file "/home/travis/build/icyphy/ptII/ptolemy/configs/test/checkFullConstraints.tcl" line 53)<br>
<br>
<code>java.lang.Exception: Evaluating the Tcl file "/home/travis/build/icyphy/ptII/ptolemy/configs/test/checkFullConstraints.tcl"resulted in a TclException being thrown.<br>The Tcl errorInfo variable could not be obtained.<br>java.lang.Exception: Evaluating the Tcl file "/home/travis/build/icyphy/ptII/ptolemy/configs/test/checkFullConstraints.tcl"resulted in a TclException being thrown.<br>The Tcl errorInfo global variable has the value:<br>ptolemy.kernel.util.InvalidStateException: Failed to populate Library<br>  in .configuration.actor library.MoreLibraries.Accessors.dashboard<br>Because:<br>Loading accessor failed: GraphComponent.js<br>  in .configuration.actor library.MoreLibraries.Accessors.dashboard<br>Because:<br>https://ptolemy.berkeley.edu/accessors/dashboard/GraphComponent.js<br>    while executing<br>"$configuration allAtomicEntityList"<br>    invoked from within<br>"set entityList [$configuration allAtomicEntityList]"<br>    (procedure "checkConstraints" line 33)<br>    invoked from within<br>"checkConstraints full/configuration.xml"<br>    (file "/home/travis/build/icyphy/ptII/ptolemy/configs/test/checkFullConstraints.tcl" line 53)<br>	at ptolemy.util.test.junit.TclTests.RunTclFile(TclTests.java:260)<br>	at junitparams.internal.InvokeParameterisedMethod.evaluate(InvokeParameterisedMethod.java:102)<br>	at junitparams.internal.ParameterisedTestMethodRunner.runMethodInvoker(ParameterisedTestMethodRunner.java:47)<br>	at junitparams.internal.ParameterisedTestMethodRunner.runTestMethod(ParameterisedTestMethodRunner.java:41)<br>	at junitparams.internal.ParameterisedTestClassRunner.runParameterisedTest(ParameterisedTestClassRunner.java:143)<br>	at junitparams.JUnitParamsRunner.runChild(JUnitParamsRunner.java:237)<br>	at junitparams.JUnitParamsRunner.runChild(JUnitParamsRunner.java:215)<br>Caused by: java.lang.reflect.InvocationTargetException<br>	at ptolemy.util.test.junit.TclTests.RunTclFile(TclTests.java:233)<br>Caused by: tcl.lang.ReflectException<br>	at tcl.lang.JavaInvoke.call(JavaInvoke.java:257)<br>	at tcl.lang.JavaInvoke.callMethod(JavaInvoke.java:116)<br>	at tcl.lang.ReflectObject.cmdProc(ReflectObject.java:727)<br>	at tcl.lang.Parser.evalObjv(Parser.java:740)<br>	at tcl.lang.Parser.eval2(Parser.java:1138)<br>	at tcl.lang.Parser.evalTokens(Parser.java:930)<br>	at tcl.lang.Parser.eval2(Parser.java:1125)<br>	at tcl.lang.Procedure.cmdProc(Procedure.java:175)<br>	at tcl.lang.Parser.evalObjv(Parser.java:740)<br>	at tcl.lang.Parser.eval2(Parser.java:1138)<br>	at tcl.lang.Interp.eval(Interp.java:1782)<br>	at tcl.lang.Interp.evalFile(Interp.java:1880)<br>
</code></td><td>12.999</td>
</tr>
</table>
</body>
</html>
